Workbook

Sheet README
A1: Irish Continental Group plc – DCF valuation vs the €8.00 Bluefin offer
A2: Prepared by Jaazim Jaseel as an independent exercise using only publicly available information. Not investment advice. Not affiliated with ICG, Bluefin or any adviser.
A4: How to read this model
A5: Blue text = hardcoded inputs (sourced in the Sources column or cell comments). Black = formulas. Green = links to another sheet. Yellow fill = key assumptions to flex.
A6: Units: € millions unless stated. Per-share figures in €. Valuation date 30 June 2026 (latest reported balance sheet).
A7: Method: unlevered free cash flow (FCFF) for H2 2026 to FY2030, mid-period discounting, Gordon growth terminal value, exit-multiple cross-check.
A8: IFRS 16: EBITDA is post-IFRS 16, so lease liabilities are deducted as debt in the equity bridge (same treatment on both sides).
A10: Sheets
A11: Historicals – FY2023 to FY2025, H1 2025, H1 2026 and LTM to June 2026, from published accounts.
A12: Assumptions – every forecast and WACC input in one place.
A13: DCF – forecast, FCFF, discounting, EV-to-equity bridge, value per share vs offer.
A14: Sensitivity – value per share across WACC and terminal growth.
... A16: Sources – documents used.

Sheet Historicals
A1: Historical financials (€m)
A3: €m | B3: FY2023 | C3: FY2024 | D3: FY2025 | E3: H1 2025 | F3: H1 2026 | G3: LTM Jun-26 | H3: Source / note
A4: Revenue | B4: 572 | C4: 603.8 | D4: 666.7 | E4: 309.9 | F4: 359.9 | G4: =D4+F4-E4 -> 716.7 | H4: FY: ICG Full Year Results 2025 (preliminary statement, Mar 2026): https://icg.ie/wp-content/uploads/2026/03/Full-Year-Results-2025.pdf ; FY2023: ICG Preliminary Statement 2024 Results (Mar 2025): https://icg.ie/wp-content/uploads/2025/03/Preliminary-Statement-2024-Results-FINAL.pdf ; H1: ICG Half-Yearly Financial Report 2026 (19 Aug 2026): https://icg.ie/wp-content/uploads/2026/08/2026i-ICG-Half-Year-Report-Final-PDF.pdf
A5: Ferries revenue (incl. inter-segment) | B5: 412.3 | C5: 433.5 | D5: 465.5 | E5: 206 | F5: 237.9 | G5: =D5+F5-E5 -> 497.4
A6: Container & Terminal revenue | B6: 194.1 | C6: 203.5 | D6: 234.6 | E6: 119.3 | F6: 137.5 | G6: =D6+F6-E6 -> 252.8
A7: Operating profit (EBIT) | B7: 68.4 | C7: 69.1 | D7: 85.6 | E7: 24.6 | F7: 24 | G7: =D7+F7-E7 -> 85
A8: Depreciation & amortisation | B8: 64.2 | C8: 64.4 | D8: 65 | E8: 30.3 | F8: 34.9 | G8: =D8+F8-E8 -> 69.6
A9: EBITDA (post-IFRS 16) | B9: =B7+B8 -> 132.6 | C9: =C7+C8 -> 133.5 | D9: =D7+D8 -> 150.6 | E9: =E7+E8 -> 54.9 | F9: =F7+F8 -> 58.9 | G9: =D9+F9-E9 -> 154.6 | H9: Formula: EBIT + D&A
A10: Ferries EBITDA | B10: 106.9 | C10: 109.8 | D10: 120.7 | E10: 40 | F10: 41.9 | G10: =D10+F10-E10 -> 122.6
A11: Container & Terminal EBITDA | B11: 25.7 | C11: 23.7 | D11: 29.9 | E11: 14.9 | F11: 17 | G11: =D11+F11-E11 -> 32
A12: Fuel and ETS costs | B12: 106.8 | C12: 109.5 | D12: 110.5 | E12: 54 | F12: 64.2 | G12: =D12+F12-E12 -> 120.7
A13: Share-based payment expense | C13: 3.6 | D13: 3.8 | E13: 2 | F13: 2.1 | G13: =D13+F13-E13 -> 3.9 | H13: FY2023 not captured
A14: Lease principal repayments | B14: 18 | C14: 14.6 | D14: 8 | E14: 4 | F14: 6.4 | G14: =D14+F14-E14 -> 10.4
A15: Capital expenditure (cash) | B15: 41.9 | C15: 29.9 | D15: 102 | E15: 90.2 | F15: 95.2 | G15: =D15+F15-E15 -> 107
A16: of which maintenance capex | B16: 21.5 | C16: 16.6 | D16: 19.4 | H16: Maintenance capex not split at half-year
A17: Cash generated from operations | B17: 136.7 | C17: 142.5 | D17: 162.2 | E17: 67.7 | F17: 89.3 | G17: =D17+F17-E17 -> 183.8
A18: Inventories (period end) | B18: 4 | C18: 11.1 | D18: 13.1 | E18: 16.8 | F18: 22.8 | G18: =F18 -> 22.8
A19: Trade & other receivables | B19: 68.6 | C19: 73.2 | D19: 82.6 | E19: 86.4 | F19: 113.7 | G19: =F19 -> 113.7
A20: Trade & other payables | B20: 93.7 | C20: 106.3 | D20: 131 | E20: 135.7 | F20: 185.7 | G20: =F20 -> 185.7
A21: Net working capital | B21: =B18+B19-B20 -> -21.1 | C21: =C18+C19-C20 -> -22 | D21: =D18+D19-D20 -> -35.3 | E21: =E18+E19-E20 -> -32.5 | F21: =F18+F19-F20 -> -49.2 | G21: =F21 -> -49.2 | H21: Formula: inventories + receivables − payables (negative = customers/suppliers fund the business)
A22: Cash | B22: 46.8 | C22: 41.3 | D22: 36.7 | E22: 17.8 | F22: 36.8 | G22: =F22 -> 36.8
A23: Bank loans | C23: 97.3 | D23: 171.3 | E23: 140 | F23: 215 | G23: =F23 -> 215 | H23: FY2023 bank loans not captured; FY2023 borrowings were €153.5m
A24: Lease liabilities | B24: 37 | C24: 107.1 | D24: 122.6 | E24: 103 | F24: 49.7 | G24: =F24 -> 49.7
A25: Reported net debt | B25: 143.7 | C25: 162.2 | D25: 256.1 | E25: 224.1 | F25: 226.2 | G25: =F25 -> 226.2 | H25: As reported: bank loans + leases − cash − capitalised origination fees
A26: Net pension surplus | B26: 38.9 | C26: 51.8 | D26: 63.3 | E26: 55.6 | F26: 68.3 | G26: =F26 -> 68.3
A27: Cars carried ('000) | B27: 645.7 | C27: 707.3 | D27: 679.7 | E27: 264.9 | F27: 249.7 | G27: =D27+F27-E27 -> 664.5 | H27: LTM column for balance sheet rows = 30 Jun 2026 balance
A28: RoRo freight units ('000) | B28: 724 | C28: 767.2 | D28: 816.7 | E28: 393.3 | F28: 409.5 | G28: =D28+F28-E28 -> 832.9
A29: Containers shipped (teu '000) | B29: 275.5 | C29: 317.8 | D29: 370 | E29: 192.9 | F29: 195.1 | G29: =D29+F29-E29 -> 372.2
A31: Ratios
A32: EBITDA margin | B32: =IFERROR(B9/B4,0) -> 0.23181818 | C32: =IFERROR(C9/C4,0) -> 0.2210997 | D32: =IFERROR(D9/D4,0) -> 0.22588871 | E32: =IFERROR(E9/E4,0) -> 0.17715392 | F32: =IFERROR(F9/F4,0) -> 0.16365657 | G32: =IFERROR(G9/G4,0) -> 0.2157109
A33: Fuel & ETS as % of revenue | B33: =IFERROR(B12/B4,0) -> 0.18671329 | C33: =IFERROR(C12/C4,0) -> 0.18135144 | D33: =IFERROR(D12/D4,0) -> 0.16574171 | E33: =IFERROR(E12/E4,0) -> 0.17424976 | F33: =IFERROR(F12/F4,0) -> 0.17838288 | G33: =IFERROR(G12/G4,0) -> 0.16841077
A34: Capex as % of revenue | B34: =IFERROR(B15/B4,0) -> 0.073251748 | C34: =IFERROR(C15/C4,0) -> 0.049519709 | D34: =IFERROR(D15/D4,0) -> 0.15299235 | E34: =IFERROR(E15/E4,0) -> 0.29106163 | F34: =IFERROR(F15/F4,0) -> 0.26451792 | G34: =IFERROR(G15/G4,0) -> 0.14929538
A35: NWC as % of LTM/FY revenue | B35: =IFERROR(B21/B4,0) -> -0.036888112 | C35: =IFERROR(C21/C4,0) -> -0.036435906 | D35: =IFERROR(D21/D4,0) -> -0.052947353 | G35: =IFERROR(G21/G4,0) -> -0.06864797
A36: Cash conversion (cash from ops / EBITDA) | B36: =IFERROR(B17/B9,0) -> 1.0309201 | C36: =IFERROR(C17/C9,0) -> 1.0674157 | D36: =IFERROR(D17/D9,0) -> 1.0770252 | E36: =IFERROR(E17/E9,0) -> 1.2331512 | F36: =IFERROR(F17/F9,0) -> 1.516129 | G36: =IFERROR(G17/G9,0) -> 1.1888745

Sheet Assumptions
A1: Assumptions (€m unless stated)
A3: Input | B3: Value | C3: Basis / source
A4: Valuation date | B4: 30-Jun-2026 | C4: Latest reported balance sheet (H1 2026)
A5: Offer price per share (€) | B5: 8 | C5: Rule 2.7 Announcement, Recommended Cash Offer for ICG by Bluefin Bidco (24 Jul 2026)
A6: Shares in issue (m) | B6: 148.46686 | C6: Rule 2.7 Announcement, Recommended Cash Offer for ICG by Bluefin Bidco (24 Jul 2026): 148,466,858 shares
A7: Outstanding share awards (m) | B7: 3.503061 | C7: Rule 2.7 Announcement, Recommended Cash Offer for ICG by Bluefin Bidco (24 Jul 2026): awards over 3,503,061 shares (treated as fully dilutive)
A8: Net debt at 30 Jun 2026 (reported) | B8: =Historicals!F25 -> 226.2 | C8: Link: H1 2026 net debt incl. €49.7m leases
A9: H2 2026 revenue change vs H2 2025 | B9: 0 | C9: Flat: higher container volumes and surcharges offset car (−7.9%) and RoRo (−9.3%) volume declines to 15 Aug 2026 (H1 2026 report)
A10: H2 2026 EBITDA change vs H2 2025 | B10: -0.08 | C10: Peak-season volume weakness, P&O Dover–Calais space charter termination notice, full ETS phase-in. Judgment.
A11: Revenue growth 2027–2030 (p.a.) | B11: 0.03 | C11: Roughly inflation plus modest freight/container growth. 2023–25 revenue CAGR was 8.0%, partly fuel surcharge-driven.
A12: EBITDA margin 2027 | B12: 0.215 | C12: 2023–25 margins 23.2%, 22.1%, 22.6%. Recovery from 2026 but below 2023 given ETS cost.
A13: EBITDA margin 2028–2030 | B13: 0.22 | C13: Mid-point of 2024–25 margins
A14: D&A as % of revenue (tax shield only) | B14: 0.0975 | C14: FY2025 D&A €65.0m / revenue €666.7m
A15: H2 2026 capex | B15: 15 | C15: H1 2026 capex €95.2m included the Oscar Wilde purchase; contracted commitments only €6.6m at 30 Jun 2026
A16: Sustainable capex 2027+ as % of revenue | B16: 0.075 | C16: Set near PP&E depreciation (FY2025 €53.7m, 8.1% of revenue) to fund fleet renewal, well above reported maintenance capex (€19.4m). Key judgment.
A17: Cash tax rate | B17: 0.035 | C17: ICG's shipping activities are taxed under the tonnage tax regime. FY2025 tax €2.6m on PBT €77.5m (3.4%)
A18: Year-end NWC as % of revenue | B18: -0.045 | C18: Dec 2023 −3.7%, Dec 2024 −3.6%, Dec 2025 −5.3% (Historicals ratios)
A19: Risk-free rate | B19: 0.0359 | C19: Irish 10-year government bond yield, 16 Oct 2026 (Trading Economics)
A20: Equity risk premium | B20: 0.055 | C20: Assumption, mature-market range 5–6%
... A26: Exit EV/EBITDA multiple (cross-check) | B26: 8 | C26: Between listed peers (DFDS 5.1x LTM, Viking Line 7.8x) and the 9.8x offer multiple
A28: WACC build
A29: Cost of equity | B29: =Assumptions!$B$19+Assumptions!$B$21*Assumptions!$B$20+Assumptions!$B$22 -> 0.0959
A30: After-tax cost of debt | B30: =Assumptions!$B$23*(1-Assumptions!$B$17) -> 0.043425
A31: WACC | B31: =(1-Assumptions!$B$24)*Assumptions!$B$29+Assumptions!$B$24*Assumptions!$B$30 -> 0.085405

Sheet DCF
A1: DCF – unlevered free cash flow (€m)
A2: Valuation date 30 June 2026. H2 2026E is a half-year period; mid-period discounting.
A4: €m | B4: H2 2025A | C4: H2 2026E | D4: FY2027E | E4: FY2028E | F4: FY2029E | G4: FY2030E
A5: Revenue | B5: =Historicals!D4-Historicals!E4 -> 356.8 | C5: =B5*(1+Assumptions!$B$9) -> 356.8 | D5: =C22*(1+Assumptions!$B$11) -> 738.201 | E5: =D5*(1+Assumptions!$B$11) -> 760.34703 | F5: =E5*(1+Assumptions!$B$11) -> 783.15744 | G5: =F5*(1+Assumptions!$B$11) -> 806.65216
A6: Revenue growth | C6: =C5/B5-1 -> 0 | D6: =D5/C22-1 -> 0.03 | E6: =E5/D5-1 -> 0.03 | F6: =F5/E5-1 -> 0.03 | G6: =G5/F5-1 -> 0.03
A7: EBITDA | B7: =Historicals!D9-Historicals!E9 -> 95.7 | C7: =B7*(1+Assumptions!$B$10) -> 88.044 | D7: =D5*Assumptions!$B$12 -> 158.71321 | E7: =E5*Assumptions!$B$13 -> 167.27635 | F7: =F5*Assumptions!$B$13 -> 172.29464 | G7: =G5*Assumptions!$B$13 -> 177.46348
A8: EBITDA margin | B8: =B7/B5 -> 0.26821749 | C8: =C7/C5 -> 0.24676009 | D8: =D7/D5 -> 0.215 | E8: =E7/E5 -> 0.22 | F8: =F7/F5 -> 0.22 | G8: =G7/G5 -> 0.22
A9: D&A (tax shield) | C9: =-C5*Assumptions!$B$14 -> -34.788 | D9: =-D5*Assumptions!$B$14 -> -71.974598 | E9: =-E5*Assumptions!$B$14 -> -74.133835 | F9: =-F5*Assumptions!$B$14 -> -76.35785 | G9: =-G5*Assumptions!$B$14 -> -78.648586
A10: EBIT | C10: =C7+C9 -> 53.256 | D10: =D7+D9 -> 86.738618 | E10: =E7+E9 -> 93.142511 | F10: =F7+F9 -> 95.936787 | G10: =G7+G9 -> 98.81489
A11: Cash tax | C11: =-MAX(0,C10)*Assumptions!$B$17 -> -1.86396 | D11: =-MAX(0,D10)*Assumptions!$B$17 -> -3.0358516 | E11: =-MAX(0,E10)*Assumptions!$B$17 -> -3.2599879 | F11: =-MAX(0,F10)*Assumptions!$B$17 -> -3.3577875 | G11: =-MAX(0,G10)*Assumptions!$B$17 -> -3.4585212
A12: Capex | C12: =-Assumptions!$B$15 -> -15 | D12: =-D5*Assumptions!$B$16 -> -55.365075 | E12: =-E5*Assumptions!$B$16 -> -57.026027 | F12: =-F5*Assumptions!$B$16 -> -58.736808 | G12: =-G5*Assumptions!$B$16 -> -60.498912
A13: Closing NWC | B13: =Historicals!D21 -> -35.3 | C13: =C22*Assumptions!$B$18 -> -32.2515 | D13: =D5*Assumptions!$B$18 -> -33.219045 | E13: =E5*Assumptions!$B$18 -> -34.215616 | F13: =F5*Assumptions!$B$18 -> -35.242085 | G13: =G5*Assumptions!$B$18 -> -36.299347
A14: Change in NWC (increase = outflow) | C14: =-(C13-C24) -> -16.9485 | D14: =-(D13-C13) -> 0.967545 | E14: =-(E13-D13) -> 0.99657135 | F14: =-(F13-E13) -> 1.0264685 | G14: =-(G13-F13) -> 1.0572625
A15: Unlevered FCF | C15: =C7+C11+C12+C14 -> 54.23154 | D15: =D7+D11+D12+D14 -> 101.27983 | E15: =E7+E11+E12+E14 -> 107.9869 | F15: =F7+F11+F12+F14 -> 111.22651 | G15: =G7+G11+G12+G14 -> 114.56331
A17: Discount period (years from valuation date) | C17: 0.25 | D17: =C17+0.75 -> 1 | E17: =D17+1 -> 2 | F17: =E17+1 -> 3 | G17: =F17+1 -> 4
A18: Discount factor | C18: =1/(1+Assumptions!$B$31)^C17 -> 0.97972016 | D18: =1/(1+Assumptions!$B$31)^D17 -> 0.92131509 | E18: =1/(1+Assumptions!$B$31)^E17 -> 0.84882149 | F18: =1/(1+Assumptions!$B$31)^F17 -> 0.78203204 | G18: =1/(1+Assumptions!$B$31)^G17 -> 0.72049792
A19: PV of FCF | C19: =C15*C18 -> 53.131733 | D19: =D15*D18 -> 93.310638 | E19: =E15*E18 -> 91.661603 | F19: =F15*F18 -> 86.982694 | G19: =G15*G18 -> 82.542623
A22: Memo: FY2026E revenue (H1 actual + H2E) | C22: =Historicals!F4+C5 -> 716.7
A23: Memo: FY2026E EBITDA (H1 actual + H2E) | C23: =Historicals!F9+C7 -> 146.944
A24: Memo: opening NWC at 30 Jun 2026 | C24: =Historicals!F21 -> -49.2
A27: Valuation – perpetuity growth method
A28: WACC | B28: =Assumptions!$B$31 -> 0.085405
A29: Terminal growth rate | B29: =Assumptions!$B$25 -> 0.02
A30: Sum of PV of FCF (H2 2026–2030) | B30: =SUM(C19:G19) -> 407.62929
A31: Terminal value at end-2030 | B31: =G15*(1+B29)/(B28-B29) -> 1786.6306
A32: Discount period for terminal value (years) | B32: =G17+0.5 -> 4.5
A33: PV of terminal value | B33: =B31/(1+B28)^B32 -> 1235.582
A34: Enterprise value | B34: =B30+B33 -> 1643.2113
A35: Less: net debt at 30 Jun 2026 (incl. leases) | B35: =-Assumptions!$B$8 -> -226.2
A36: Equity value | B36: =B34+B35 -> 1417.0113
A37: Fully diluted shares (m) | B37: =Assumptions!$B$6+Assumptions!$B$7 -> 151.96992
A38: Value per share (€) | B38: =B36/B37 -> 9.3242881
A39: Offer price per share (€) | B39: =Assumptions!$B$5 -> 8
A40: Offer premium / (discount) to DCF value | B40: =B39/B38-1 -> -0.14202565
A41: PV of terminal value as % of EV | B41: =B33/B34 -> 0.7519313
A42: Implied exit EV/EBITDA (TV / FY2030 EBITDA) | B42: =B31/G7 -> 10.067596
A43: Implied EV / FY2025 EBITDA | B43: =B34/Historicals!D9 -> 10.911098
A45: Cross-check – exit multiple method
A46: Exit EV/EBITDA multiple | B46: =Assumptions!$B$26 -> 8
A47: Terminal value at end-2030 | B47: =G7*B46 -> 1419.7078
...

Sheet Sensitivity
A1: Value per share (€) – WACC vs terminal growth
A2: Each cell recomputes EV from the DCF sheet's FCF row with its own WACC and growth rate. Offer = €8.00.
A4: WACC ↓ / g → | B4: 0.01 | C4: 0.015 | D4: 0.02 | E4: 0.025 | F4: 0.03
A5: 0.07 | B5: =(SUMPRODUCT(DCF!$C$15:$G$15,1/(1+$A5)^DCF!$C$17:$G$17)+DCF!$G$15*(1+B$4)/($A5-B$4)/(1+$A5)^DCF!$B$32-Assumptions!$B$8)/DCF!$B$37 -> 10.637509 | C5: =(SUMPRODUCT(DCF!$C$15:$G$15,1/(1+$A5)^DCF!$C$17:$G$17)+DCF!$G$15*(1+C$4)/($A5-C$4)/(1+$A5)^DCF!$B$32-Assumptions!$B$8)/DCF!$B$37 -> 11.538874 | D5: =(SUMPRODUCT(DCF!$C$15:$G$15,1/(1+$A5)^DCF!$C$17:$G$17)+DCF!$G$15*(1+D$4)/($A5-D$4)/(1+$A5)^DCF!$B$32-Assumptions!$B$8)/DCF!$B$37 -> 12.620512 | E5: =(SUMPRODUCT(DCF!$C$15:$G$15,1/(1+$A5)^DCF!$C$17:$G$17)+DCF!$G$15*(1+E$4)/($A5-E$4)/(1+$A5)^DCF!$B$32-Assumptions!$B$8)/DCF!$B$37 -> 13.942514 | F5: =(SUMPRODUCT(DCF!$C$15:$G$15,1/(1+$A5)^DCF!$C$17:$G$17)+DCF!$G$15*(1+F$4)/($A5-F$4)/(1+$A5)^DCF!$B$32-Assumptions!$B$8)/DCF!$B$37 -> 15.595017
A6: 0.075 | B6: =(SUMPRODUCT(DCF!$C$15:$G$15,1/(1+$A6)^DCF!$C$17:$G$17)+DCF!$G$15*(1+B$4)/($A6-B$4)/(1+$A6)^DCF!$B$32-Assumptions!$B$8)/DCF!$B$37 -> 9.7102418 | C6: =(SUMPRODUCT(DCF!$C$15:$G$15,1/(1+$A6)^DCF!$C$17:$G$17)+DCF!$G$15*(1+C$4)/($A6-C$4)/(1+$A6)^DCF!$B$32-Assumptions!$B$8)/DCF!$B$37 -> 10.460591 | D6: =(SUMPRODUCT(DCF!$C$15:$G$15,1/(1+$A6)^DCF!$C$17:$G$17)+DCF!$G$15*(1+D$4)/($A6-D$4)/(1+$A6)^DCF!$B$32-Assumptions!$B$8)/DCF!$B$37 -> 11.347368 | E6: =(SUMPRODUCT(DCF!$C$15:$G$15,1/(1+$A6)^DCF!$C$17:$G$17)+DCF!$G$15*(1+E$4)/($A6-E$4)/(1+$A6)^DCF!$B$32-Assumptions!$B$8)/DCF!$B$37 -> 12.4115 | F6: =(SUMPRODUCT(DCF!$C$15:$G$15,1/(1+$A6)^DCF!$C$17:$G$17)+DCF!$G$15*(1+F$4)/($A6-F$4)/(1+$A6)^DCF!$B$32-Assumptions!$B$8)/DCF!$B$37 -> 13.712106
A7: 0.08 | B7: =(SUMPRODUCT(DCF!$C$15:$G$15,1/(1+$A7)^DCF!$C$17:$G$17)+DCF!$G$15*(1+B$4)/($A7-B$4)/(1+$A7)^DCF!$B$32-Assumptions!$B$8)/DCF!$B$37 -> 8.9161557 | C7: =(SUMPRODUCT(DCF!$C$15:$G$15,1/(1+$A7)^DCF!$C$17:$G$17)+DCF!$G$15*(1+C$4)/($A7-C$4)/(1+$A7)^DCF!$B$32-Assumptions!$B$8)/DCF!$B$37 -> 9.5489512 | D7: =(SUMPRODUCT(DCF!$C$15:$G$15,1/(1+$A7)^DCF!$C$17:$G$17)+DCF!$G$15*(1+D$4)/($A7-D$4)/(1+$A7)^DCF!$B$32-Assumptions!$B$8)/DCF!$B$37 -> 10.287213 | E7: =(SUMPRODUCT(DCF!$C$15:$G$15,1/(1+$A7)^DCF!$C$17:$G$17)+DCF!$G$15*(1+E$4)/($A7-E$4)/(1+$A7)^DCF!$B$32-Assumptions!$B$8)/DCF!$B$37 -> 11.159703 | F7: =(SUMPRODUCT(DCF!$C$15:$G$15,1/(1+$A7)^DCF!$C$17:$G$17)+DCF!$G$15*(1+F$4)/($A7-F$4)/(1+$A7)^DCF!$B$32-Assumptions!$B$8)/DCF!$B$37 -> 12.206692
A8: 0.085 | B8: =(SUMPRODUCT(DCF!$C$15:$G$15,1/(1+$A8)^DCF!$C$17:$G$17)+DCF!$G$15*(1+B$4)/($A8-B$4)/(1+$A8)^DCF!$B$32-Assumptions!$B$8)/DCF!$B$37 -> 8.2285869 | C8: =(SUMPRODUCT(DCF!$C$15:$G$15,1/(1+$A8)^DCF!$C$17:$G$17)+DCF!$G$15*(1+C$4)/($A8-C$4)/(1+$A8)^DCF!$B$32-Assumptions!$B$8)/DCF!$B$37 -> 8.7682149 | D8: =(SUMPRODUCT(DCF!$C$15:$G$15,1/(1+$A8)^DCF!$C$17:$G$17)+DCF!$G$15*(1+D$4)/($A8-D$4)/(1+$A8)^DCF!$B$32-Assumptions!$B$8)/DCF!$B$37 -> 9.3908627 | E8: =(SUMPRODUCT(DCF!$C$15:$G$15,1/(1+$A8)^DCF!$C$17:$G$17)+DCF!$G$15*(1+E$4)/($A8-E$4)/(1+$A8)^DCF!$B$32-Assumptions!$B$8)/DCF!$B$37 -> 10.117285 | F8: =(SUMPRODUCT(DCF!$C$15:$G$15,1/(1+$A8)^DCF!$C$17:$G$17)+DCF!$G$15*(1+F$4)/($A8-F$4)/(1+$A8)^DCF!$B$32-Assumptions!$B$8)/DCF!$B$37 -> 10.975784
A9: 0.09 | B9: =(SUMPRODUCT(DCF!$C$15:$G$15,1/(1+$A9)^DCF!$C$17:$G$17)+DCF!$G$15*(1+B$4)/($A9-B$4)/(1+$A9)^DCF!$B$32-Assumptions!$B$8)/DCF!$B$37 -> 7.6275386 | C9: =(SUMPRODUCT(DCF!$C$15:$G$15,1/(1+$A9)^DCF!$C$17:$G$17)+DCF!$G$15*(1+C$4)/($A9-C$4)/(1+$A9)^DCF!$B$32-Assumptions!$B$8)/DCF!$B$37 -> 8.0921757 | D9: =(SUMPRODUCT(DCF!$C$15:$G$15,1/(1+$A9)^DCF!$C$17:$G$17)+DCF!$G$15*(1+D$4)/($A9-D$4)/(1+$A9)^DCF!$B$32-Assumptions!$B$8)/DCF!$B$37 -> 8.6231896 | E9: =(SUMPRODUCT(DCF!$C$15:$G$15,1/(1+$A9)^DCF!$C$17:$G$17)+DCF!$G$15*(1+E$4)/($A9-E$4)/(1+$A9)^DCF!$B$32-Assumptions!$B$8)/DCF!$B$37 -> 9.2358979 | F9: =(SUMPRODUCT(DCF!$C$15:$G$15,1/(1+$A9)^DCF!$C$17:$G$17)+DCF!$G$15*(1+F$4)/($A9-F$4)/(1+$A9)^DCF!$B$32-Assumptions!$B$8)/DCF!$B$37 -> 9.9507243
A10: 0.095 | B10: =(SUMPRODUCT(DCF!$C$15:$G$15,1/(1+$A10)^DCF!$C$17:$G$17)+DCF!$G$15*(1+B$4)/($A10-B$4)/(1+$A10)^DCF!$B$32-Assumptions!$B$8)/DCF!$B$37 -> 7.0977203 | C10: =(SUMPRODUCT(DCF!$C$15:$G$15,1/(1+$A10)^DCF!$C$17:$G$17)+DCF!$G$15*(1+C$4)/($A10-C$4)/(1+$A10)^DCF!$B$32-Assumptions!$B$8)/DCF!$B$37 -> 7.5011794 | D10: =(SUMPRODUCT(DCF!$C$15:$G$15,1/(1+$A10)^DCF!$C$17:$G$17)+DCF!$G$15*(1+D$4)/($A10-D$4)/(1+$A10)^DCF!$B$32-Assumptions!$B$8)/DCF!$B$37 -> 7.9584331 | E10: =(SUMPRODUCT(DCF!$C$15:$G$15,1/(1+$A10)^DCF!$C$17:$G$17)+DCF!$G$15*(1+E$4)/($A10-E$4)/(1+$A10)^DCF!$B$32-Assumptions!$B$8)/DCF!$B$37 -> 8.4810088 | F10: =(SUMPRODUCT(DCF!$C$15:$G$15,1/(1+$A10)^DCF!$C$17:$G$17)+DCF!$G$15*(1+F$4)/($A10-F$4)/(1+$A10)^DCF!$B$32-Assumptions!$B$8)/DCF!$B$37 -> 9.0839807
A12: Value per share (€) – WACC vs exit EV/EBITDA multiple
A14: WACC ↓ / multiple → | B14: 7 | C14: 7.5 | D14: 8 | E14: 8.5 | F14: 9 | G14: 9.5 | H14: 10
A15: 0.07 | B15: =(SUMPRODUCT(DCF!$C$15:$G$15,1/(1+$A15)^DCF!$C$17:$G$17)+DCF!$G$7*B$14/(1+$A15)^DCF!$B$32-Assumptions!$B$8)/DCF!$B$37 -> 7.3071569 | C15: =(SUMPRODUCT(DCF!$C$15:$G$15,1/(1+$A15)^DCF!$C$17:$G$17)+DCF!$G$7*C$14/(1+$A15)^DCF!$B$32-Assumptions!$B$8)/DCF!$B$37 -> 7.7377771 | D15: =(SUMPRODUCT(DCF!$C$15:$G$15,1/(1+$A15)^DCF!$C$17:$G$17)+DCF!$G$7*D$14/(1+$A15)^DCF!$B$32-Assumptions!$B$8)/DCF!$B$37 -> 8.1683973 | E15: =(SUMPRODUCT(DCF!$C$15:$G$15,1/(1+$A15)^DCF!$C$17:$G$17)+DCF!$G$7*E$14/(1+$A15)^DCF!$B$32-Assumptions!$B$8)/DCF!$B$37 -> 8.5990174 | F15: =(SUMPRODUCT(DCF!$C$15:$G$15,1/(1+$A15)^DCF!$C$17:$G$17)+DCF!$G$7*F$14/(1+$A15)^DCF!$B$32-Assumptions!$B$8)/DCF!$B$37 -> 9.0296376 | G15: =(SUMPRODUCT(DCF!$C$15:$G$15,1/(1+$A15)^DCF!$C$17:$G$17)+DCF!$G$7*G$14/(1+$A15)^DCF!$B$32-Assumptions!$B$8)/DCF!$B$37 -> 9.4602577 | H15: =(SUMPRODUCT(DCF!$C$15:$G$15,1/(1+$A15)^DCF!$C$17:$G$17)+DCF!$G$7*H$14/(1+$A15)^DCF!$B$32-Assumptions!$B$8)/DCF!$B$37 -> 9.8908779
A16: 0.075 | B16: =(SUMPRODUCT(DCF!$C$15:$G$15,1/(1+$A16)^DCF!$C$17:$G$17)+DCF!$G$7*B$14/(1+$A16)^DCF!$B$32-Assumptions!$B$8)/DCF!$B$37 -> 7.1540095 | C16: =(SUMPRODUCT(DCF!$C$15:$G$15,1/(1+$A16)^DCF!$C$17:$G$17)+DCF!$G$7*C$14/(1+$A16)^DCF!$B$32-Assumptions!$B$8)/DCF!$B$37 -> 7.5756897 | D16: =(SUMPRODUCT(DCF!$C$15:$G$15,1/(1+$A16)^DCF!$C$17:$G$17)+DCF!$G$7*D$14/(1+$A16)^DCF!$B$32-Assumptions!$B$8)/DCF!$B$37 -> 7.99737 | E16: =(SUMPRODUCT(DCF!$C$15:$G$15,1/(1+$A16)^DCF!$C$17:$G$17)+DCF!$G$7*E$14/(1+$A16)^DCF!$B$32-Assumptions!$B$8)/DCF!$B$37 -> 8.4190503 | F16: =(SUMPRODUCT(DCF!$C$15:$G$15,1/(1+$A16)^DCF!$C$17:$G$17)+DCF!$G$7*F$14/(1+$A16)^DCF!$B$32-Assumptions!$B$8)/DCF!$B$37 -> 8.8407305 | G16: =(SUMPRODUCT(DCF!$C$15:$G$15,1/(1+$A16)^DCF!$C$17:$G$17)+DCF!$G$7*G$14/(1+$A16)^DCF!$B$32-Assumptions!$B$8)/DCF!$B$37 -> 9.2624108 | H16: =(SUMPRODUCT(DCF!$C$15:$G$15,1/(1+$A16)^DCF!$C$17:$G$17)+DCF!$G$7*H$14/(1+$A16)^DCF!$B$32-Assumptions!$B$8)/DCF!$B$37 -> 9.684091
A17: 0.08 | B17: =(SUMPRODUCT(DCF!$C$15:$G$15,1/(1+$A17)^DCF!$C$17:$G$17)+DCF!$G$7*B$14/(1+$A17)^DCF!$B$32-Assumptions!$B$8)/DCF!$B$37 -> 7.0045294 | C17: =(SUMPRODUCT(DCF!$C$15:$G$15,1/(1+$A17)^DCF!$C$17:$G$17)+DCF!$G$7*C$14/(1+$A17)^DCF!$B$32-Assumptions!$B$8)/DCF!$B$37 -> 7.4174956 | D17: =(SUMPRODUCT(DCF!$C$15:$G$15,1/(1+$A17)^DCF!$C$17:$G$17)+DCF!$G$7*D$14/(1+$A17)^DCF!$B$32-Assumptions!$B$8)/DCF!$B$37 -> 7.8304617 | E17: =(SUMPRODUCT(DCF!$C$15:$G$15,1/(1+$A17)^DCF!$C$17:$G$17)+DCF!$G$7*E$14/(1+$A17)^DCF!$B$32-Assumptions!$B$8)/DCF!$B$37 -> 8.2434279 | F17: =(SUMPRODUCT(DCF!$C$15:$G$15,1/(1+$A17)^DCF!$C$17:$G$17)+DCF!$G$7*F$14/(1+$A17)^DCF!$B$32-Assumptions!$B$8)/DCF!$B$37 -> 8.656394 | G17: =(SUMPRODUCT(DCF!$C$15:$G$15,1/(1+$A17)^DCF!$C$17:$G$17)+DCF!$G$7*G$14/(1+$A17)^DCF!$B$32-Assumptions!$B$8)/DCF!$B$37 -> 9.0693602 | H17: =(SUMPRODUCT(DCF!$C$15:$G$15,1/(1+$A17)^DCF!$C$17:$G$17)+DCF!$G$7*H$14/(1+$A17)^DCF!$B$32-Assumptions!$B$8)/DCF!$B$37 -> 9.4823263
A18: 0.085 | B18: =(SUMPRODUCT(DCF!$C$15:$G$15,1/(1+$A18)^DCF!$C$17:$G$17)+DCF!$G$7*B$14/(1+$A18)^DCF!$B$32-Assumptions!$B$8)/DCF!$B$37 -> 6.8586107 | C18: =(SUMPRODUCT(DCF!$C$15:$G$15,1/(1+$A18)^DCF!$C$17:$G$17)+DCF!$G$7*C$14/(1+$A18)^DCF!$B$32-Assumptions!$B$8)/DCF!$B$37 -> 7.2630819 | D18: =(SUMPRODUCT(DCF!$C$15:$G$15,1/(1+$A18)^DCF!$C$17:$G$17)+DCF!$G$7*D$14/(1+$A18)^DCF!$B$32-Assumptions!$B$8)/DCF!$B$37 -> 7.667553 | E18: =(SUMPRODUCT(DCF!$C$15:$G$15,1/(1+$A18)^DCF!$C$17:$G$17)+DCF!$G$7*E$14/(1+$A18)^DCF!$B$32-Assumptions!$B$8)/DCF!$B$37 -> 8.0720241 | F18: =(SUMPRODUCT(DCF!$C$15:$G$15,1/(1+$A18)^DCF!$C$17:$G$17)+DCF!$G$7*F$14/(1+$A18)^DCF!$B$32-Assumptions!$B$8)/DCF!$B$37 -> 8.4764953 | G18: =(SUMPRODUCT(DCF!$C$15:$G$15,1/(1+$A18)^DCF!$C$17:$G$17)+DCF!$G$7*G$14/(1+$A18)^DCF!$B$32-Assumptions!$B$8)/DCF!$B$37 -> 8.8809664 | H18: =(SUMPRODUCT(DCF!$C$15:$G$15,1/(1+$A18)^DCF!$C$17:$G$17)+DCF!$G$7*H$14/(1+$A18)^DCF!$B$32-Assumptions!$B$8)/DCF!$B$37 -> 9.2854375
A19: 0.09 | B19: =(SUMPRODUCT(DCF!$C$15:$G$15,1/(1+$A19)^DCF!$C$17:$G$17)+DCF!$G$7*B$14/(1+$A19)^DCF!$B$32-Assumptions!$B$8)/DCF!$B$37 -> 6.7161509 | C19: =(SUMPRODUCT(DCF!$C$15:$G$15,1/(1+$A19)^DCF!$C$17:$G$17)+DCF!$G$7*C$14/(1+$A19)^DCF!$B$32-Assumptions!$B$8)/DCF!$B$37 -> 7.1123397 | D19: =(SUMPRODUCT(DCF!$C$15:$G$15,1/(1+$A19)^DCF!$C$17:$G$17)+DCF!$G$7*D$14/(1+$A19)^DCF!$B$32-Assumptions!$B$8)/DCF!$B$37 -> 7.5085284 | E19: =(SUMPRODUCT(DCF!$C$15:$G$15,1/(1+$A19)^DCF!$C$17:$G$17)+DCF!$G$7*E$14/(1+$A19)^DCF!$B$32-Assumptions!$B$8)/DCF!$B$37 -> 7.9047171 | F19: =(SUMPRODUCT(DCF!$C$15:$G$15,1/(1+$A19)^DCF!$C$17:$G$17)+DCF!$G$7*F$14/(1+$A19)^DCF!$B$32-Assumptions!$B$8)/DCF!$B$37 -> 8.3009059 | G19: =(SUMPRODUCT(DCF!$C$15:$G$15,1/(1+$A19)^DCF!$C$17:$G$17)+DCF!$G$7*G$14/(1+$A19)^DCF!$B$32-Assumptions!$B$8)/DCF!$B$37 -> 8.6970946 | H19: =(SUMPRODUCT(DCF!$C$15:$G$15,1/(1+$A19)^DCF!$C$17:$G$17)+DCF!$G$7*H$14/(1+$A19)^DCF!$B$32-Assumptions!$B$8)/DCF!$B$37 -> 9.0932833
A20: 0.095 | B20: =(SUMPRODUCT(DCF!$C$15:$G$15,1/(1+$A20)^DCF!$C$17:$G$17)+DCF!$G$7*B$14/(1+$A20)^DCF!$B$32-Assumptions!$B$8)/DCF!$B$37 -> 6.5770511 | C20: =(SUMPRODUCT(DCF!$C$15:$G$15,1/(1+$A20)^DCF!$C$17:$G$17)+DCF!$G$7*C$14/(1+$A20)^DCF!$B$32-Assumptions!$B$8)/DCF!$B$37 -> 6.9651637 | D20: =(SUMPRODUCT(DCF!$C$15:$G$15,1/(1+$A20)^DCF!$C$17:$G$17)+DCF!$G$7*D$14/(1+$A20)^DCF!$B$32-Assumptions!$B$8)/DCF!$B$37 -> 7.3532764 | E20: =(SUMPRODUCT(DCF!$C$15:$G$15,1/(1+$A20)^DCF!$C$17:$G$17)+DCF!$G$7*E$14/(1+$A20)^DCF!$B$32-Assumptions!$B$8)/DCF!$B$37 -> 7.7413891 | F20: =(SUMPRODUCT(DCF!$C$15:$G$15,1/(1+$A20)^DCF!$C$17:$G$17)+DCF!$G$7*F$14/(1+$A20)^DCF!$B$32-Assumptions!$B$8)/DCF!$B$37 -> 8.1295018 | G20: =(SUMPRODUCT(DCF!$C$15:$G$15,1/(1+$A20)^DCF!$C$17:$G$17)+DCF!$G$7*G$14/(1+$A20)^DCF!$B$32-Assumptions!$B$8)/DCF!$B$37 -> 8.5176144 | H20: =(SUMPRODUCT(DCF!$C$15:$G$15,1/(1+$A20)^DCF!$C$17:$G$17)+DCF!$G$7*H$14/(1+$A20)^DCF!$B$32-Assumptions!$B$8)/DCF!$B$37 -> 8.9057271

Sheet Offer & peers
A1: Offer EV bridge and peer multiples
A3: €m | B3: Value | C3: Note
A4: Offer price per share (€) | B4: =Assumptions!$B$5 -> 8 | C4: Link
A5: Fully diluted shares (m) | B5: =Assumptions!$B$6+Assumptions!$B$7 -> 151.96992 | C5: Shares in issue + outstanding awards
A6: Equity value at offer | B6: =B4*B5 -> 1215.7594 | C6: Offer announcement: ~€1.2bn fully diluted
A7: Net debt 31 Dec 2025 (incl. leases) | B7: =Historicals!D25 -> 256.1 | C7: Offer announcement EV of ~€1.47bn reconciles to Dec-25 net debt
A8: Enterprise value at offer | B8: =B6+B7 -> 1471.8594 | C8: Offer announcement: ~€1.47bn
A9: EV / FY2025 EBITDA | B9: =B8/Historicals!D9 -> 9.7733025 | C9: Offer announcement: ~9.8x
A10: Net debt 30 Jun 2026 (incl. leases) | B10: =Assumptions!$B$8 -> 226.2 | C10: Latest reported
A11: EV at offer on Jun-26 net debt | B11: =B6+B10 -> 1441.9594
A12: EV / LTM Jun-26 EBITDA | B12: =B11/Historicals!G9 -> 9.3270333 | C12: LTM EBITDA = FY25 + H1 26 − H1 25
A13: Premium to pre-offer close (€6.24, 24 Jul 2026) | B13: =B4/6.24-1 -> 0.28205128 | C13: Offer announcement: 28.2%
A16: Listed ferry peer | B16: EV / EBITDA | C16: Basis and source
A17: DFDS (Denmark) | B17: 5.1 | C17: LTM, multiples.vc, data as of 14 Oct 2026
A18: Viking Line (Finland) | B18: 7.8 | C18: Last fiscal year, multiples.vc, data as of 4 Sep 2026
A19: Peer average | B19: =AVERAGE(B17:B18) -> 6.45
A20: Offer multiple (FY2025) | B20: =B9 -> 9.7733025
A22: Peers are imperfect: DFDS is far larger and more freight/logistics-heavy; Viking Line is Baltic passenger-focused. ICG's Container & Terminal division (~20% of EBITDA) has some port-infrastructure character, which objecting shareholders argued deserves a higher multiple.

Sheet Sources
A1: Sources
A3: ICG Full Year Results 2025 (preliminary statement, Mar 2026): https://icg.ie/wp-content/uploads/2026/03/Full-Year-Results-2025.pdf
A4: ICG Half-Yearly Financial Report 2026 (19 Aug 2026): https://icg.ie/wp-content/uploads/2026/08/2026i-ICG-Half-Year-Report-Final-PDF.pdf
A5: ICG Preliminary Statement 2024 Results (Mar 2025): https://icg.ie/wp-content/uploads/2025/03/Preliminary-Statement-2024-Results-FINAL.pdf
A6: Rule 2.7 Announcement, Recommended Cash Offer for ICG by Bluefin Bidco (24 Jul 2026): https://www.investegate.co.uk/announcement/gnw/irish-continental-group-units-comp-cdi---icgc/recommended-cash-offer-for-irish-continental-/9687462
A7: Irish Times, 10 Sep 2026: scheme approved by 79.2% of votes cast
A8: Irish 10-year yield: https://tradingeconomics.com/ireland/government-bond-yield (16 Oct 2026)
A9: Peer multiples: https://multiples.vc/public-comps/dfds-valuation-multiples ; https://multiples.vc/public-comps/viking-line-valuation-multiples
